Traceback (most recent call last):
  File "/opt/hostedtoolcache/Python/3.8.16/x64/lib/python3.8/site-packages/jupyter_cache/executors/utils.py", line 58, in single_nb_execution
    executenb(
  File "/opt/hostedtoolcache/Python/3.8.16/x64/lib/python3.8/site-packages/nbclient/client.py", line 1204, in execute
    return NotebookClient(nb=nb, resources=resources, km=km, **kwargs).execute()
  File "/opt/hostedtoolcache/Python/3.8.16/x64/lib/python3.8/site-packages/nbclient/util.py", line 84, in wrapped
    return just_run(coro(*args, **kwargs))
  File "/opt/hostedtoolcache/Python/3.8.16/x64/lib/python3.8/site-packages/nbclient/util.py", line 62, in just_run
    return loop.run_until_complete(coro)
  File "/opt/hostedtoolcache/Python/3.8.16/x64/lib/python3.8/asyncio/base_events.py", line 616, in run_until_complete
    return future.result()
  File "/opt/hostedtoolcache/Python/3.8.16/x64/lib/python3.8/site-packages/nbclient/client.py", line 663, in async_execute
    await self.async_execute_cell(
  File "/opt/hostedtoolcache/Python/3.8.16/x64/lib/python3.8/site-packages/nbclient/client.py", line 965, in async_execute_cell
    await self._check_raise_for_error(cell, cell_index, exec_reply)
  File "/opt/hostedtoolcache/Python/3.8.16/x64/lib/python3.8/site-packages/nbclient/client.py", line 862, in _check_raise_for_error
    raise CellExecutionError.from_cell_and_msg(cell, exec_reply_content)
nbclient.exceptions.CellExecutionError: An error occurred while executing the following cell:
------------------
gridder = gridding.Gridder(
    cell_size=0.005,  # [arcsec]
    npix=800,
    uu=uu,
    vv=vv,
    weight=weight,
    data_re=data_re,
    data_im=data_im,
)
------------------

[0;31m---------------------------------------------------------------------------[0m
[0;31mTypeError[0m                                 Traceback (most recent call last)
Cell [0;32mIn[12], line 1[0m
[0;32m----> 1[0m gridder [38;5;241m=[39m [43mgridding[49m[38;5;241;43m.[39;49m[43mGridder[49m[43m([49m
[1;32m      2[0m [43m    [49m[43mcell_size[49m[38;5;241;43m=[39;49m[38;5;241;43m0.005[39;49m[43m,[49m[43m  [49m[38;5;66;43;03m# [arcsec][39;49;00m
[1;32m      3[0m [43m    [49m[43mnpix[49m[38;5;241;43m=[39;49m[38;5;241;43m800[39;49m[43m,[49m
[1;32m      4[0m [43m    [49m[43muu[49m[38;5;241;43m=[39;49m[43muu[49m[43m,[49m
[1;32m      5[0m [43m    [49m[43mvv[49m[38;5;241;43m=[39;49m[43mvv[49m[43m,[49m
[1;32m      6[0m [43m    [49m[43mweight[49m[38;5;241;43m=[39;49m[43mweight[49m[43m,[49m
[1;32m      7[0m [43m    [49m[43mdata_re[49m[38;5;241;43m=[39;49m[43mdata_re[49m[43m,[49m
[1;32m      8[0m [43m    [49m[43mdata_im[49m[38;5;241;43m=[39;49m[43mdata_im[49m[43m,[49m
[1;32m      9[0m [43m)[49m

[0;31mTypeError[0m: __init__() got an unexpected keyword argument 'cell_size'
TypeError: __init__() got an unexpected keyword argument 'cell_size'

